Workbook
Name acqui: '[1]DONNEES TECHNIQUES'!$F$25
Name age_max: '[2]EVALUATION CAPITAL CONST'!$D$6
Name Age_prêt: '[1]PRET RBM PER'!$F$14
Name agemax_ascendant: '[3]DONNEES TECH'!$H$13
Name agemax_enfant: '[3]DONNEES TECH'!$H$11
Name agesimulprêt: '[3]SIMULATION COLL EMPRUNT'!$J$10
Name AGRES: #REF!
Name AGRES: #REF!
Name AGRES: #REF!
Name AGRES: #REF!
Name AGRES: #REF!
Name AGRES: #REF!
Name AGRES: #REF!
Name AGRES: #REF!
Name base: #REF!
Name base: #REF!
Name base: #REF!
Name base: #REF!
Name base: #REF!
Name base: #REF!
Name base: #REF!
Name base: #REF!
Name capfad1: [3]FICHETARIFICATION!$I$15
Name capfad2: [3]FICHETARIFICATION!$I$16
Name capfad3: [3]FICHETARIFICATION!$I$17
Name capfco1: [3]FICHETARIFICATION!$J$15
Name capfco2: [3]FICHETARIFICATION!$J$16
Name capfco3: [3]FICHETARIFICATION!$J$17
Name capfen1: [3]FICHETARIFICATION!$K$15
Name capfen2: [3]FICHETARIFICATION!$K$16
Name capfen3: [3]FICHETARIFICATION!$K$17
Name coût_avn: '[3]DONNEES TECH'!#REF!
Name coût_avn: '[3]DONNEES TECH'!#REF!
Name coût_avn: '[3]DONNEES TECH'!#REF!
Name coût_avn: '[3]DONNEES TECH'!#REF!
Name coût_avn: '[3]DONNEES TECH'!#REF!
Name coût_avn: '[3]DONNEES TECH'!#REF!
Name coût_avn: '[3]DONNEES TECH'!#REF!
Name coût_avn: '[3]DONNEES TECH'!#REF!
Name d: #REF!
Name d: #REF!
Name d: #REF!
Name d: #REF!
Name d: #REF!
Name d: #REF!
Name d: #REF!
Name d: #REF!
Name d_m: #REF!
Name d_m: #REF!
Name d_m: #REF!
Name d_m: #REF!
Name d_m: #REF!
Name d_m: #REF!
Name d_m: #REF!
Name d_m: #REF!
Name d_prêt: #REF!
Name d_prêt: #REF!
Name d_prêt: #REF!
Name d_prêt: #REF!
Name d_prêt: #REF!

Sheet HYPPOTHESE ACTUARIELLE
A1: Hypothèses actuarielles
A3: Taux d'intérêt | B3: i | C3: =3.5/100 -> 0.035
A4: Taux d'intérêt périodique | B4: ip | C4: =+-1+(1+taux_interêt)^(1/4) -> 0.008637446
A5: Facteur d'actualisation | B5: v | C5: =+(1/(1+taux_interêt)) -> 0.96618357
A6: Age maximum | B6: w | C6: 106
A7: Frais de gestion | B7: g | C7: 0.05
A8: Pénalité de rachat | B8: pr | C8: 0.05
A9: Date d'évaluation | B9: Dat_Eval | C9: =TODAY() -> 46226

Sheet Synthèse 2021
C2: MOUVEMENT AFFAIRES DIRECTES "SANTE DU RETRAITE" (ETAT CIMA C-20)
B4: MOUVEMENT AFFAIRES DIRECTES "AMAT-CI SANTE DU RETRAITE"
A6: EN COURS A L'OUVERTURE DE L'EXERCICE (2021) | C6: 44286 | E6: 44377 | G6: 44469 | I6: 44561 | K6: TOTAL
C7: Nbre | D7: Montant | E7: Nbre | F7: Montant | G7: Nbre | H7: Montant | I7: Nbre | J7: Montant | K7: Nbre | L7: Montant
A8: ENTRÉES | B8: Souscriptions (Precompte) | C8: 21 | D8: 15252700 | E8: 57 | F8: 35571510 | G8: 95 | H8: 42389059 | I8: 181 | J8: 65674580 | K8: 178 | L8: =D8+F8+H8+J8 -> 158887849
B9: Remplacements ou Transformations (Avance, Cash, Virement) | C9: 3 | D9: 22878500 | E9: 1 | F9: 685900 | G9: 6 | H9: =53890977-42389059 -> 11501918 | I9: 0 | J9: =94498780-65674580 -> 28824200 | L9: =D9+F9+H9+J9 -> 63890518
B10: Revalorisations | G10: =SUM(C10:F10) -> 0 | L10: =D10+F10+H10+J10 -> 0
B11: TOTAL DES ENTREES | C11: =SUM(C8:C10) -> 24 | D11: =SUM(D8:D10) -> 38131200 | E11: =SUM(E8:E10) -> 58 | F11: =SUM(F8:F10) -> 36257410 | G11: =SUM(G8:G10) -> 101 | H11: =SUM(H8:H10) -> 53890977 | I11: =SUM(I8:I10) -> 181 | J11: =SUM(J8:J10) -> 94498780 | K11: 178 | L11: =D11+F11+H11+J11 -> 222778367
A13: SORTIES | B13: Sans effet | L13: =D13+F13+H13+J13 -> 0
B14: Remplacements ou Transformations | L14: =D14+F14+H14+J14 -> 0
B15: Échéances | E15: 0 | I15: 3 | J15: 0 | L15: =D15+F15+H15+J15 -> 0
B16: Sinistres | C16: 0 | L16: =D16+F16+H16+J16 -> 0
B17: Extinctions | L17: =D17+F17+H17+J17 -> 0
B18: Rachats | L18: =D18+F18+H18+J18 -> 0
B19: Réductions | L19: =D19+F19+H19+J19 -> 0
B20: Résiliations | C20: 0 | D20: 0 | L20: =D20+F20+H20+J20 -> 0
B21: TOTAL DES SORTIES | C21: =SUM(C13:C20) -> 0 | D21: =SUM(D13:D20) -> 0 | L21: =D21+F21+H21+J21 -> 0
A22: TOTAL (ENTREES - SORTIES) | C22: =+C11-C21 -> 24 | D22: =+D11-D21 -> 38131200 | E22: =+E11-E21 -> 58 | F22: =+F11-F21 -> 36257410 | G22: =+G11-G21 -> 101 | H22: =+H11-H21 -> 53890977 | I22: =+I8-I15-I16 -> 178 | J22: =J11-J21 -> 94498780 | K22: 178 | L22: =L11-L21 -> 222778367
A23: EN COURS A LA CLOTURE DE L'EXERCICE (2021)
D25: =+D22*(1+ip) -> 38460556 | F25: =+D25+(F22*(1+ip)) -> 75031138 | H25: =+F25+(H22*(1+ip)) -> 1.293876e+08 | J25: =+H25+(J22*(1+ip)) -> 2.247026e+08 | L25: =+L22*(1+3.5%) -> 2.3057561e+08

Sheet Synthèse 2022
C2: MOUVEMENT AFFAIRES DIRECTES "SANTE DU RETRAITE" (ETAT CIMA C-20)
B4: MOUVEMENT AFFAIRES DIRECTES "AMAT-CI SANTE DU RETRAITE"
A6: EN COURS A L'OUVERTURE DE L'EXERCICE (2021) | C6: 44651 | E6: 44742 | G6: 44834 | I6: 44926 | K6: TOTAL
C7: Nbre | D7: Montant | E7: Nbre | F7: Montant | G7: Nbre | H7: Montant | I7: Nbre | J7: Montant | K7: Nbre | L7: Montant
A8: ENTRÉES | B8: Souscriptions (Precompte) | C8: 265 | D8: 92478806 | E8: 360 | F8: 101995556 | G8: 377 | H8: 103942376 | I8: 436 | J8: 132436444 | L8: =D8+F8+H8+J8 -> 430853182
B9: Remplacements ou Transformations (Avance, Cash, Virement) | C9: 2 | D9: 5268400 | E9: 4 | F9: 10293600 | G9: 5 | H9: 32372300 | I9: 7 | J9: 29360700 | L9: =D9+F9+H9+J9 -> 77295000
B10: Revalorisations | G10: 27 | H10: 5898533 | L10: =D10+F10+H10+J10 -> 5898533
B11: TOTAL DES ENTREES | C11: =SUM(C8:C10) -> 267 | D11: =SUM(D8:D10) -> 97747206 | E11: =SUM(E8:E10) -> 364 | F11: =SUM(F8:F10) -> 112289156 | G11: =SUM(G8:G10) -> 409 | H11: =SUM(H8:H10) -> 142213209 | I11: =SUM(I8:I10) -> 443 | J11: =SUM(J8:J10) -> 161797144 | L11: =D11+F11+H11+J11 -> 514046715
A13: SORTIES | B13: Sans effet | L13: =D13+F13+H13+J13 -> 0
B14: Remplacements ou Transformations | F14: =362600+813000+228400+267600+68000 -> 1739600 | L14: =D14+F14+H14+J14 -> 1739600
B15: Échéances | C15: r3 | D15: 522372 | E15: r5 | F15: =522372+475160 -> 997532 | G15: r7 | H15: =997532+475160 -> 1472692 | I15: r11 | J15: =1472692+696496 -> 2169188 | L15: =D15+F15+H15+J15 -> 5161784
B16: Sinistres | C16: 0 | E16: 1 | F16: 1767876 | L16: =D16+F16+H16+J16 -> 1767876
B17: Extinctions | L17: =D17+F17+H17+J17 -> 0
B18: Rachats | I18: 0 | L18: =D18+F18+H18+J18 -> 0
B19: Réductions | L19: =D19+F19+H19+J19 -> 0
B20: Résiliations | C20: 7 | D20: 2434600 | E20: 0 | F20: 0 | G20: 3 | H20: =329443+3688629+173867 -> 4191939 | I20: 6 | J20: =100000+184000+197898+1382852+413182+127987 -> 2405919 | L20: =D20+F20+H20+J20 -> 9032458
B21: TOTAL DES SORTIES | C21: =SUM(C13:C20) -> 7 | D21: =SUM(D13:D20) -> 2956972 | E21: =SUM(E13:E20) -> 1 | F21: =SUM(F13:F20) -> 4505008 | G21: =SUM(G13:G20) -> 3 | H21: =SUM(H13:H20) -> 5664631 | I21: =SUM(I13:I20) -> 6 | J21: =SUM(J13:J20) -> 4575107 | K21: =SUM(K13:K20) -> 0 | L21: =D21+F21+H21+J21 -> 17701718
A22: TOTAL (ENTREES - SORTIES) | C22: =+C11-C21 -> 260 | D22: =+D11-D21 -> 94790234 | E22: =+E11-E21 -> 363 | F22: =+F11-F21 -> 107784148 | G22: =+G11-G21 -> 406 | H22: =+H11-H21 -> 136548578 | I22: =I11-I21 -> 437 | J22: =J11-J21 -> 157222037 | L22: =L11-L21 -> 496344997
A23: EN COURS A LA CLOTURE DE L'EXERCICE (2021)

Sheet Synthèse 2023
C2: MOUVEMENT AFFAIRES DIRECTES "SANTE DU RETRAITE" (ETAT CIMA C-20)
B4: MOUVEMENT AFFAIRES DIRECTES "AMAT-CI SANTE DU RETRAITE"
A6: EN COURS A L'OUVERTURE DE L'EXERCICE (2023) | C6: 45016 | E6: 45107 | G6: 45199 | I6: 45291 | K6: TOTAL
C7: Nbre | D7: Montant | E7: Nbre | F7: Montant | G7: Nbre | H7: Montant | I7: Nbre | J7: Montant | K7: Nbre | L7: Montant
A8: ENTRÉES | B8: Souscriptions (Precompte) | C8: 562 | D8: 139875962 | E8: 668 | F8: =144114285+352200 -> 144466485 | G8: 743 | H8: 150704451 | I8: =772+9 -> 781 | J8: =151746631+756700 -> 152503331 | L8: =D8+F8+H8+J8 -> 587550229
B9: Remplacements ou Transformations (Avance, Cash, Virement) | C9: 3 | D9: =1512700+4462400+2884200 -> 8859300 | E9: 1 | F9: 3859260 | G9: 5 | H9: 20007800 | I9: 3 | J9: =1673400+3030000+11843804+5000000 -> 21547204 | L9: =D9+F9+H9+J9 -> 54273564
B10: Revalorisations | L10: =D10+F10+H10+J10 -> 0
B11: TOTAL DES ENTREES | C11: =SUM(C8:C10) -> 565 | D11: =SUM(D8:D10) -> 148735262 | E11: =SUM(E8:E10) -> 669 | F11: =SUM(F8:F10) -> 148325745 | G11: =SUM(G8:G10) -> 748 | H11: =SUM(H8:H10) -> 170712251 | I11: =SUM(I8:I10) -> 784 | J11: =SUM(J8:J10) -> 174050535 | ... L11: =SUM(L8:L10) -> 641823793
A13: SORTIES | B13: Sans effet | L13: =D13+F13+H13+J13 -> 0
B14: Remplacements ou Transformations | L14: =D14+F14+H14+J14 -> 0
B15: Retraité année antérieur SDR | C15: 15 | D15: =3039808-D16 -> 2865684 | E15: 16 | F15: 3039808 | G15: 19 | H15: 3689092 | I15: 21 | J15: 4164252 | L15: =D15+F15+H15+J15 -> 13758836
B16: Échéances (Retraité année en cours) | C16: 1 | D16: 174124 | E16: 3 | F16: =174124+301036+174124 -> 649284 | G16: 2 | H16: =301036+174124 -> 475160 | I16: 2 | J16: =174124+174124 -> 348248 | L16: =D16+F16+H16+J16 -> 1646816
B17: Sinistres | C17: 0 | L17: =D17+F17+H17+J17 -> 0
B18: Extinctions | L18: =D18+F18+H18+J18 -> 0
B19: Rachats | L19: =D19+F19+H19+J19 -> 0
B20: Réductions | L20: =D20+F20+H20+J20 -> 0
B21: Résiliations | C21: 4 | D21: =67453+45515+934088+3459041 -> 4506097 | E21: 8 | F21: 9565833 | G21: 9 | H21: 4330053 | I21: 1 | J21: 677824 | L21: =D21+F21+H21+J21 -> 19079807
B22: TOTAL DES SORTIES | C22: =SUM(C13:C21)-C15 -> 5 | D22: =SUM(D13:D21) -> 7545905 | E22: =SUM(E13:E21)-E15 -> 11 | F22: =SUM(F13:F21) -> 13254925 | G22: =SUM(G13:G21)-G15 -> 11 | H22: =SUM(H13:H21) -> 8494305 | I22: =SUM(I13:I21)-I15 -> 3 | J22: =SUM(J13:J21) -> 5190324 | K22: =SUM(K13:K21) -> 0 | L22: =D22+F22+H22+J22 -> 34485459
A23: TOTAL (ENTREES - SORTIES) | C23: =+C11-C22 -> 560 | D23: =+D11-D22 -> 141189357 | E23: =+E11-E22 -> 658 | F23: =+F11-F22 -> 135070820 | G23: =+G11-G22 -> 737 | H23: =+H11-H22 -> 162217946 | I23: =+I11-I22 -> 781 | J23: =+J11-J22 -> 168860211 | K23: =SUM(K13:K22) -> 0 | L23: =L11-L22 -> 607338334
A24: EN COURS A LA CLOTURE DE L'EXERCICE (2023)
H28: =+D11+F11+H11 -> 467773258 | J28: =+D11+F11+H11+J11 -> 641823793
F29: =222778367+496344997+446378679 -> 1165502043 | H29: =+D23+F23+H23 -> 438478123 | J29: =+D23+F23+H23+J23 -> 607338334

Sheet Synthèse Année 2023 Corrigé
C2: MOUVEMENT AFFAIRES DIRECTES "SANTE DU RETRAITE" (ETAT CIMA C-20)
B4: MOUVEMENT AFFAIRES DIRECTES "AMAT-CI SANTE DU RETRAITE"
A6: EN COURS A L'OUVERTURE DE L'EXERCICE (2023) | C6: 45016 | E6: 45107 | G6: 45199 | I6: 45291 | K6: TOTAL
C7: Nbre | D7: Montant | E7: Nbre | F7: Montant | G7: Nbre | H7: Montant | I7: Nbre | J7: Montant | K7: Nbre | L7: Montant
A8: ENTRÉES | B8: Souscriptions (Precompte) | C8: 562 | D8: 139875962 | E8: 668 | F8: =144114285+352200 -> 144466485 | G8: 743 | H8: 150704451 | I8: =772+9 -> 781 | J8: =151746631+756700-304500 -> 152198831 | L8: =D8+F8+H8+J8 -> 587245729
B9: Remplacements ou Transformations (Avance, Cash, Virement) | C9: 3 | D9: =1512700+4462400+2884200 -> 8859300 | E9: 1 | F9: 3859260 | G9: 5 | H9: 20007800 | I9: 7 | J9: =1673400+3030000+11849804+5000000+249500+150000+414500 -> 22367204 | L9: =D9+F9+H9+J9 -> 55093564
B10: Revalorisations | L10: =D10+F10+H10+J10 -> 0
B11: TOTAL DES ENTREES | C11: =SUM(C8:C10) -> 565 | D11: =SUM(D8:D10) -> 148735262 | E11: =SUM(E8:E10) -> 669 | F11: =SUM(F8:F10) -> 148325745 | G11: =SUM(G8:G10) -> 748 | H11: =SUM(H8:H10) -> 170712251 | I11: =SUM(I8:I10) -> 788 | J11: =SUM(J8:J10) -> 174566035 | ... L11: =SUM(L8:L10) -> 642339293
A13: SORTIES | B13: Sans effet | L13: =D13+F13+H13+J13 -> 0
B14: Remplacements ou Transformations | L14: =D14+F14+H14+J14 -> 0
B15: Retraité année antérieur SDR | C15: 17 | D15: =3641880-174124 -> 3467756 | E15: 18 | F15: 3641880 | G15: 21 | H15: 4291164 | I15: 23 | J15: 4766324 | L15: =D15+F15+H15+J15 -> 16167124
B16: Échéances (Retraité année en cours) | C16: 1 | D16: 174124 | E16: 3 | F16: =301036+174124+174124 -> 649284 | G16: 2 | H16: =301036+174124 -> 475160 | I16: 2 | J16: =301036+301036 -> 602072 | L16: =D16+F16+H16+J16 -> 1900640 | N16: =+L15+L16 -> 18067764
B17: Sinistres | C17: 0 | L17: =D17+F17+H17+J17 -> 0
B18: Extinctions | L18: =D18+F18+H18+J18 -> 0
B19: Rachats | L19: =D19+F19+H19+J19 -> 0
B20: Réductions | L20: =D20+F20+H20+J20 -> 0
B21: Résiliations | C21: 4 | D21: =67453+45515+934088+3459041 -> 4506097 | E21: 8 | F21: 9565833 | G21: 9 | H21: 4330053 | I21: 1 | J21: 677824 | L21: =D21+F21+H21+J21 -> 19079807
B22: TOTAL DES SORTIES | C22: =SUM(C13:C21)-C15 -> 5 | D22: =SUM(D13:D21) -> 8147977 | E22: =SUM(E13:E21)-E15 -> 11 | F22: =SUM(F13:F21) -> 13856997 | G22: =SUM(G13:G21)-G15 -> 11 | H22: =SUM(H13:H21) -> 9096377 | I22: =SUM(I13:I21)-I15 -> 3 | J22: =SUM(J13:J21) -> 6046220 | K22: =SUM(K13:K21) -> 0 | L22: =D22+F22+H22+J22 -> 37147571 | N22: =+L22-L21 -> 18067764
A23: TOTAL (ENTREES - SORTIES) | C23: =+C11-C22 -> 560 | D23: =+D11-D22 -> 140587285 | E23: =+E11-E22 -> 658 | F23: =+F11-F22 -> 134468748 | G23: =+G11-G22 -> 737 | H23: =+H11-H22 -> 161615874 | I23: =+I11-I22 -> 785 | J23: =+J11-J22 -> 168519815 | K23: =SUM(K13:K22) -> 0 | L23: =L11-L22 -> 605191722
A24: EN COURS A LA CLOTURE DE L'EXERCICE (2023)
L26: =+L11-L23 -> 37147571
J27: =5241484-174124+301036 -> 5368396
H28: =+D11+F11+H11 -> 467773258 | J28: =+D11+F11+H11+J11 -> 642339293 | L28: =4766324-4512500 -> 253824
F29: =222778367+496344997+446378679 -> 1165502043 | H29: =+D23+F23+H23 -> 436671907 | J29: =+D23+F23+H23+J23 -> 605191722 | L29: =+L28-174124 -> 79700

Sheet Synthèse Année 2024
C2: MOUVEMENT AFFAIRES DIRECTES "SANTE DU RETRAITE" (ETAT CIMA C-20)
B4: MOUVEMENT AFFAIRES DIRECTES "AMAT-CI SANTE DU RETRAITE"
A6: EN COURS A L'OUVERTURE DE L'EXERCICE (2024) | C6: 45382 | E6: 45473 | G6: 45565 | I6: 45657 | K6: TOTAL
C7: Nbre | D7: Montant | E7: Nbre | F7: Montant | G7: Nbre | H7: Montant | I7: Nbre | J7: Montant | K7: Nbre | L7: Montant
A8: ENTRÉES | B8: Souscriptions (Precompte) | C8: 831 | D8: =157980231 -> 157980231 | E8: 1010 | F8: 171584484 | G8: 1034 | H8: 172600084 | I8: 1069 | J8: 181250034 | L8: =D8+F8+H8+J8 -> 683414833
B9: Remplacements ou Transformations (Avance, Cash, Virement) | C9: 1 | D9: 11095800 | E9: 8 | F9: =10695800+1000000+223200+7000000+4000000+414500+8961100+402200+50000 -> 32746800 | G9: 5 | H9: =200000+70000+2857180+50000+272200 -> 3449380 | I9: 6 | J9: =874000+1665000+50000+7317400+6030278+5068300 -> 21004978 | L9: =+D9+F9+H9+J9 -> 68296958 | M9: =+D11+F11+H11+J11 -> 751711791 | N9: =5670500-602200 -> 5068300
B10: Revalorisations
B11: TOTAL DES ENTREES | C11: =SUM(C8:C10) -> 832 | D11: =SUM(D8:D10) -> 169076031 | E11: =SUM(E8:E10) -> 1018 | F11: =SUM(F8:F10) -> 204331284 | G11: =SUM(G8:G10) -> 1039 | H11: =SUM(H8:H10) -> 176049464 | I11: =SUM(I8:I10) -> 1075 | J11: =SUM(J8:J10) -> 202255012 | ... L11: =SUM(L8:L10) -> 751711791 | M11: =+L11-751711791 -> 0
A13: SORTIES | B13: Sans effet
B14: Remplacements ou Transformations
B15: Retraité année antérieur SDR | C15: 25 | D15: =4766324+602072 -> 5368396 | E15: 28 | F15: =4766324+602072+649284 -> 6017680 | G15: 36 | H15: =4766324+602072+649284+1900640 -> 7918320 | I15: =36+1 -> 37 | J15: =4766324+602072+649284+1900640 -> 7918320 | L15: =D15+F15+H15+J15 -> 27222716
B16: Échéances (Retraité année en cours) | C16: 3 | D16: 649284 | E16: 8 | F16: 1900640 | G16: 1 | H16: 0 | I16: 1 | J16: 0 | L16: =+D16+F16+H16+J16 -> 2549924
B17: Sinistres | C17: 0 | E17: 0 | G17: 0 | I17: 0 | K17: 0
B18: Extinctions
B19: Rachats
B20: Réductions
B21: Résiliations | C21: 3 | D21: 1335404 | E21: 10 | F21: 3104190 | G21: 6 | H21: 9071282 | I21: 6 | J21: 2045222 | L21: =D21+F21+H21+J21 -> 15556098
B22: TOTAL DES SORTIES | C22: =SUM(C13:C21)-C15 -> 6 | D22: =SUM(D13:D21) -> 7353084 | E22: =SUM(E13:E21)-E15 -> 18 | F22: =SUM(F13:F21) -> 11022510 | G22: =SUM(G13:G21)-G15 -> 7 | H22: =SUM(H13:H21) -> 16989602 | I22: =SUM(I13:I21)-I15 -> 7 | J22: =SUM(J13:J21) -> 9963542 | L22: =SUM(L13:L21) -> 45328738
A23: TOTAL (ENTREES - SORTIES) | C23: =+C11-C22 -> 826 | D23: =+D11-D22 -> 161722947 | E23: =+E11-E22 -> 1000 | F23: =+F11-F22 -> 193308774 | G23: =+G11-G22 -> 1032 | H23: =+H11-H22 -> 159059862 | I23: =+I11-I22 -> 1068 | J23: =+J11-J22 -> 192291470 | L23: =+L11-L22 -> 706383053
A24: EN COURS A LA CLOTURE DE L'EXERCICE (2024)
J27: =5241484-174124+301036 -> 5368396 | L27: =+D23+F23+H23+J23 -> 706383053
H28: =+D11+F11+H11 -> 549456779 | J28: =+D11+F11+H11+J11 -> 751711791 | L28: =4766324-4512500 -> 253824
F29: =222778367+496344997+446378679 -> 1165502043 | H29: =+D23+F23+H23 -> 514091583 | J29: =+D23+F23+H23+J23 -> 706383053 | L29: =+L28-174124 -> 79700

Sheet PM AMAT-CI SDR sur entrée
B3: SYNTHESE DES PROVISIONS MATHEMATIQUES POUR LE PRODUIT AMAT-CI SANTE DU RETRAITE
B5: 1) Les cotisations trimestrielles durant l'année 2021
D6: PM Formule Récurrence | E6: PM Annuelle Formule direct
B7: Total cotisation trimestre (1) | C7: ='Synthèse 2021'!D11 -> 38131200 | D7: =+C7*(1+ip) -> 38460556 | H7: =+C7*(1+ip)^3 -> 39127828
B8: Total cotisation trimestre (2) | C8: ='Synthèse 2021'!F11 -> 36257410 | D8: =+D7+(C8*(1+ip)) -> 75031138 | H8: =+C8*(1+ip)^2 -> 36886458
B9: Total cotisation trimestre (3) | C9: ='Synthèse 2021'!H11 -> 53890977 | D9: =+D8+(C9*(1+ip)) -> 1.293876e+08 | H9: =+C9*(1+ip)^1 -> 54356457
B10: Total cotisation trimestre (4) | C10: ='Synthèse 2021'!J11 -> 94498780 | D10: =+D9+(C10*(1+ip)) -> 2.247026e+08 | E10: =+C11*(1+i) -> 2.3057561e+08 | F10: =+E10-D10 -> 5873006.7 | H10: =+C10 -> 94498780
B11: Total cotisation année 2021 | C11: =SUM(C7:C10) -> 222778367 | F11: 224869523 | G11: PM 2021 | H11: =SUM(H7:H10) -> 2.2486952e+08 | I11: =+H11-D10 -> 166919.64
F12: =+E10-F11 -> 5706086.8
B14: 2) Les cotisations trimestrielles durant l'année 2022
D15: PM Formule Récurrence | E15: PM Annuelle Formule direct | H15: =+H11*1.035 -> 2.3273996e+08
B16: Total cotisation trimestre (1) | C16: =+'Synthèse 2022'!D11 -> 97747206 | D16: =+D10+(C16*(1+ip)) -> 3.232941e+08 | H16: =+C16*(1+ip)^3 -> 1.0030201e+08
B17: Total cotisation trimestre (2) | C17: =+'Synthèse 2022'!F11 -> 112289156 | D17: =+D16+(C17*(1+ip)) -> 4.3655314e+08 | H17: =+C17*(1+ip)^2 -> 1.1423732e+08
B18: Total cotisation trimestre (3) | C18: =+'Synthèse 2022'!H11 -> 142213209 | D18: =+D17+(C18*(1+ip)) -> 5.7999471e+08 | H18: =+C18*(1+ip)^1 -> 1.4344157e+08
B19: Total cotisation trimestre (4) | C19: =+'Synthèse 2022'!J11 -> 161797144 | D19: =+D18+(C19*(1+ip)) -> 7.4318937e+08 | E19: =+E10+(C20*(1+i)) -> 7.6261396e+08 | H19: =+C19 -> 161797144
B20: Total cotisation année 2022 | C20: =SUM(C16:C19) -> 514046715 | G20: PM 2022 | H20: =SUM(H15:H19) -> 7.5251799e+08 | I20: =+H20-D19 -> 9328620.6 | J20: =+'Synthèse 2022'!L21 -> 17701718
I21: =+H20-J20 -> 7.3481627e+08
C22: PM 2022 | D22: =+D19-D10 -> 5.1848677e+08 | E22: =E19-E10 -> 5.3203835e+08 | G22: Dotation 2022 | H22: =+H20-H11 -> 5.2764847e+08 | I22: =+H22-D22 -> 9161701
C23: Reprises 2022 | E23: =+E22-'PM SDR sur solde'!E21 -> 18321278
C24: Dotation 2022 | E24: =+E22-E23 -> 5.1371707e+08 | I24: =+I21-H11 -> 5.0994675e+08
B26: 3) Les cotisations trimestrielles durant l'année 2023
D27: PM Formule Récurrence | E27: PM Annuelle Formule direct | H27: =+H24*1.035 -> 0
B28: Total cotisation trimestre (1) | C28: =+'Synthèse Année 2023 Corrigé'!D11 -> 148735262 | D28: =+D19+(C28*(1+ip)) -> 8.9320932e+08 | H28: =+C28*(1+ip)^3 -> 1.5262273e+08
B29: Total cotisation trimestre (2) | C29: =+'Synthèse Année 2023 Corrigé'!F11 -> 148325745 | D29: =+D28+(C29*(1+ip)) -> 1.0428162e+09 | H29: =+C29*(1+ip)^2 -> 1.5089912e+08
B30: Total cotisation trimestre (3) | C30: =+'Synthèse Année 2023 Corrigé'!H11 -> 170712251 | D30: =+D29+(C30*(1+ip)) -> 1.215003e+09 | H30: =+C30*(1+ip)^1 -> 1.7218677e+08
B31: Total cotisation trimestre (4) | C31: =+'Synthèse Année 2023 Corrigé'!J11 -> 174566035 | D31: =+D30+(C31*(1+ip)) -> 1.3910768e+09 | E31: =+E19+(C32*(1+i)) -> 1.4274351e+09 | H31: =+C31 -> 174566035
B32: Total cotisation année 2023 | C32: =SUM(C28:C31) -> 642339293 | F32: =+C32*(1+i) -> 6.6482117e+08 | G32: PM 2022 | H32: =SUM(H27:H31) -> 6.5027465e+08 | I32: =+H32-D31 -> -7.4080218e+08
C34: PM 2023 | D34: =+D31-D19 -> 6.4788746e+08 | E34: =+E31-E19 -> 6.6482117e+08 | G34: Dotation 2023 | H34: =+H32-H24 -> 6.5027465e+08 | I34: =+H34-D34 -> 2387187.7
C35: Reprises 2023 | E35: =+E34-'PM SDR sur solde'!E32 -> 38447736
C36: Dotation 2023 | E36: =+E34-E35 -> 6.2637343e+08 | F36: =+E36+E24+E10 -> 1.3706661e+09
F37: =+F36-1362882327 -> 7783787
B38: 4) Les cotisations trimestrielles durant l'année 2024 | F38: =+F37-F10 -> 1910780.3
D39: PM Formule Récurrence | E39: PM Annuelle Formule direct
B40: Total cotisation trimestre (1) | C40: =+'Synthèse Année 2024'!D11 -> 169076031 | D40: =+D31+(C40*(1+ip)) -> 1.5616132e+09
B41: Total cotisation trimestre (2) | C41: =+'Synthèse Année 2024'!F11 -> 204331284 | D41: =+D40+(C41*(1+ip)) -> 1.7677094e+09
B42: Total cotisation trimestre (3) | C42: =+'Synthèse Année 2024'!H11 -> 176049464 | D42: =+D41+(C42*(1+ip)) -> 1.9452795e+09
B43: Total cotisation trimestre (4) | C43: =+'Synthèse Année 2024'!J11 -> 202255012 | D43: =+D42+(C43*(1+ip)) -> 2.1492815e+09 | E43: =+E31+(C44*(1+i)) -> 2.2054568e+09
B44: Total cotisation année 2024 | C44: =SUM(C40:C43) -> 751711791
C46: PM 2024 | D46: =+D43-D31 -> 7.5820466e+08 | E46: =+E43-E31 -> 7.780217e+08
C47: Reprises 2024 | E47: =+E46-'PM SDR sur solde'!E43 -> 46915244
...

Sheet PM SDR sur solde
B2: PM Final
B4: 1) Les cotisations trimestrielles durant l'année 2021
D5: PM Formule Récurrence | E5: PM Annuelle Formule direct
B6: Total cotisation trimestre (1) | C6: =+'Synthèse 2021'!D22 -> 38131200 | D6: =+C6*(1+ip) -> 38460556 | H6: =+C6*(1+ip)^3 -> 39127828
B7: Total cotisation trimestre (2) | C7: ='Synthèse 2021'!F22 -> 36257410 | D7: =+D6+(C7*(1+ip)) -> 75031138 | H7: =+C7*(1+ip)^2 -> 36886458
B8: Total cotisation trimestre (3) | C8: ='Synthèse 2021'!H22 -> 53890977 | D8: =+D7+(C8*(1+ip)) -> 1.293876e+08 | H8: =+C8*(1+ip)^1 -> 54356457
B9: Total cotisation trimestre (4) | C9: ='Synthèse 2021'!J22 -> 94498780 | D9: =+D8+(C9*(1+ip)) -> 2.247026e+08 | E9: =+C10*(1+i) -> 2.3057561e+08 | H9: =+C9 -> 94498780
B10: Total cotisation année 2021 | C10: =SUM(C6:C9) -> 222778367 | G10: PM 2021 | H10: =SUM(H6:H9) -> 2.2486952e+08 | I10: =+H10-D9 -> 166919.64
B13: 2) Les cotisations trimestrielles durant l'année 2022
D14: PM Formule Récurrence | E14: PM Annuelle Formule direct | H14: =+H10*1.035 -> 2.3273996e+08
B15: Total cotisation trimestre (1) | C15: =+'Synthèse 2022'!D22 -> 94790234 | D15: =+D9+(C15*(1+ip)) -> 3.2031158e+08 | H15: =+C15*(1+ip)^3 -> 97267747
B16: Total cotisation trimestre (2) | C16: =+'Synthèse 2022'!F22 -> 107784148 | D16: =+D15+(C16*(1+ip)) -> 4.2902671e+08 | H16: =+C16*(1+ip)^2 -> 1.0965415e+08
B17: Total cotisation trimestre (3) | C17: =+'Synthèse 2022'!H22 -> 136548578 | D17: =+D16+(C17*(1+ip)) -> 5.6675472e+08 | H17: =+C17*(1+ip)^1 -> 1.3772801e+08
B18: Total cotisation trimestre (4) | C18: =+'Synthèse 2022'!J22 -> 157222037 | D18: =+D17+(C18*(1+ip)) -> 7.2533475e+08 | E18: =+E9+(C19*(1+i)) -> 7.4429268e+08 | H18: =+C18 -> 157222037
B19: Total cotisation année 2022 | C19: =SUM(C15:C18) -> 496344997 | G19: PM 2022 | H19: =SUM(H14:H18) -> 7.346119e+08 | I19: =+H19-D18 -> 9277144.9 | J19: =+'Synthèse 2022'!L21 -> 17701718
I20: =+H19-J19 -> 7.1691018e+08
C21: Dotation 2022 | D21: =+D18-D9 -> 5.0063215e+08 | E21: =E18-E9 -> 5.1371707e+08 | G21: Dotation 2022 | H21: =+H19-H10 -> 5.0974238e+08 | I21: =+H21-D21 -> 9110225.2
I22: =+I20-H10 -> 4.9204066e+08
B24: 3) Les cotisations trimestrielles durant l'année 2023
D25: PM Formule Récurrence | E25: PM Annuelle Formule direct | H25: =+H22*1.035 -> 0
B26: Total cotisation trimestre (1) | C26: =+'Synthèse Année 2023 Corrigé'!D23 -> 140587285 | D26: =+D18+(C26*(1+ip)) -> 8.6713635e+08 | H26: =+C26*(1+ip)^3 -> 1.4426179e+08
B27: Total cotisation trimestre (2) | C27: =+'Synthèse Année 2023 Corrigé'!F23 -> 134468748 | D27: =+D26+(C27*(1+ip)) -> 1.0027666e+09 | H27: =+C27*(1+ip)^2 -> 1.3680171e+08
B28: Total cotisation trimestre (3) | C28: =+'Synthèse Année 2023 Corrigé'!H23 -> 161615874 | D28: =+D27+(C28*(1+ip)) -> 1.1657784e+09 | H28: =+C28*(1+ip)^1 -> 1.6301182e+08
B29: Total cotisation trimestre (4) | C29: =+'Synthèse Année 2023 Corrigé'!J23 -> 168519815 | D29: =+D28+(C29*(1+ip)) -> 1.3357538e+09 | E29: =+E18+(C30*(1+i)) -> 1.3706661e+09 | H29: =+C29 -> 168519815
B30: Total cotisation année 2023 | C30: =SUM(C26:C29) -> 605191722 | G30: PM 2022 | H30: =SUM(H25:H29) -> 6.1259514e+08 | I30: =+H30-D29 -> -7.2315865e+08
C32: Dotation 2023 | D32: =+D29-D18 -> 6.1041903e+08 | E32: =+E29-E18 -> 6.2637343e+08 | G32: Dotation 2023 | H32: =+H30-H22 -> 6.1259514e+08 | I32: =+H32-D32 -> 2176104.4
B35: 4) Les cotisations trimestrielles durant l'année 2024
D36: PM Formule Récurrence | E36: PM Annuelle Formule direct
B37: Total cotisation trimestre (1) | C37: =+'Synthèse Année 2024'!D23 -> 161722947 | D37: =+D29+(C37*(1+ip)) -> 1.4988736e+09
B38: Total cotisation trimestre (2) | C38: =+'Synthèse Année 2024'!F23 -> 193308774 | D38: =+D37+(C38*(1+ip)) -> 1.6938521e+09
B39: Total cotisation trimestre (3) | C39: =+'Synthèse Année 2024'!H23 -> 159059862 | D39: =+D38+(C39*(1+ip)) -> 1.8542858e+09
B40: Total cotisation trimestre (4) | C40: =+'Synthèse Année 2024'!J23 -> 192291470 | D40: =+D39+(C40*(1+ip)) -> 2.0482382e+09 | E40: =+E29+(C41*(1+i)) -> 2.1017726e+09
B41: Total cotisation année 2024 | C41: =SUM(C37:C40) -> 706383053
C43: Dotation 2023 | D43: =+D40-D29 -> 7.124844e+08 | E43: =+E40-E29 -> 7.3110646e+08

Sheet Au BILAN 
B2: RECONCILIATION DE LA PROVISION AU BILAN SUR L'EXERCICE
B3: Libellés | I3: PM Total | J3: 2023 | K3: 2022 | L3: 2021
B4: Dotation aux Provisions Mathématique | I4: =+SUM(J4:L4) -> 1.4274351e+09 | J4: =+'PM AMAT-CI SDR sur entrée'!E34 -> 6.6482117e+08 | K4: =+'PM AMAT-CI SDR sur entrée'!E22 -> 5.3203835e+08 | L4: =+'PM AMAT-CI SDR sur entrée'!E10 -> 2.3057561e+08
B5: Charge Comptable du dispositif au titre de l'exercice | K5: 0 | L5: 0
B6: Prestations payées au cours de l'exercice | K6: 0 | L6: 0
B7: Ecarts de conversion
B8: Autres
B9: PROVISION COMPTABLE DE FIN D'EXERCICE | I9: =+SUM(J9:L9) -> 1.4274351e+09 | J9: =+J4-J5-J6-J7-J8 -> 6.6482117e+08 | K9: =+K4-K5-K6-K7-K8 -> 5.3203835e+08 | L9: =+L4-L5-L6-L7-L8 -> 2.3057561e+08
B10: Remarque :

Sheet Résutat d'exploitation 2022
A3: RESULTAT D'EXPLOITATION SIMPLIFIE 2022 "AMAT-CI SANTE DU RETRAITE"
A5: DEBIT | D5: CREDIT
B6: % | C6: Montant | E6: % | F6: Montant
A7: Frais d'exploitation | B7: =C7/$C$10 -> 0 | C7: 0 | D7: Cotisations | E7: =+F7/$F$10 -> #REF! | F7: ='PM AMAT-CI SDR sur entrée'!#REF! -> #REF!
A8: Provisions | B8: =C8/$C$10 -> 0.95 | C8: =+C10*95% -> 724483262 | D8: Produits Financiers | E8: =+F8/$F$10 -> #REF! | F8: =+C10-F7 -> #REF!
A9: Bénéfice de gestion | B9: =C9/$C$10 -> 0.05 | C9: =+C10-C8 -> 38130698 | D9: Autres Produits | E9: =+F9/$F$10 -> 0 | F9: 0
A10: TOTAL | B10: 1 | C10: 762613960 | D10: TOTAL | E10: 1 | F10: =C10 -> 762613960
